Workbook

Sheet Analyse_RH_Projet.xlsx
A1: Employee_Name | B1: EmpID | C1: MarriedID | D1: MaritalStatuID | E1: GenderIS | F1: EmpstatutID | G1: DeptID | H1: PerfScoreID | I1: FromDiver | J1: Salary | K1: Termd | L1: PositionID | M1: Psition | N1: State | O1: Zip | P1: DOB | Q1: Sex | R1: MaritalDESC | S1: Citizedesc | T1: HispanicLatin | U1: Racedesc | V1: Dateofhire | W1: Dateoftermi | X1: Termreason | Y1: Employement | Z1: Department | AA1: Managernat | AB1: ManagerID | AC1: Recrutment | AD1: Performance | AE1: Engagement | AF1: EmploySatisfy | AG1: SpecialProjet | AH1: LastPERF | AI1: DayLatel | AJ1: Absences
A2: Adinolfi Wilson K | B2: 10026 | C2: 0 | D2: 0 | E2: 1 | F2: 1 | G2: 5 | H2: 4 | I2: 0 | J2: 62506 | K2: 0 | L2: 19 | M2: Production Technician I | N2: MA | O2: 1960 | P2: 30596 | Q2: M | R2: Single | S2: US Citizen | T2: No | U2: White | V2: 40670 | X2: N/A-StillEmployed | Y2: Active | Z2: Production | AA2: Michael Albert | AB2: 22 | AC2: LinkedIn | AD2: Exceeds | AE2: 4.60 | AF2: 5 | AG2: 0 | AH2: 1/17/2019 | AI2: 0 | AJ2: 1
A3: Ait Sidi Karthikeyan | B3: 10084 | C3: 1 | D3: 1 | E3: 1 | F3: 5 | G3: 3 | H3: 3 | I3: 0 | J3: 104437 | K3: 1 | L3: 27 | M3: Sr. DBA | N3: MA | O3: 2148 | P3: 27519 | Q3: M | R3: Married | S3: US Citizen | T3: No | U3: White | V3: 3/30/2015 | W3: 6/16/2016 | X3: career change | Y3: Voluntarily Terminated | Z3: IT/IS | AA3: Simon Roup | AB3: 4 | AC3: Indeed | AD3: Fully Meets | AE3: 4.96 | AF3: 3 | AG3: 6 | AH3: 2/24/2016 | AI3: 0 | AJ3: 17
A4: Akinkuolie Sarah | B4: 10196 | C4: 1 | D4: 1 | E4: 0 | F4: 5 | G4: 5 | H4: 3 | I4: 0 | J4: 64955 | K4: 1 | L4: 20 | M4: Production Technician II | N4: MA | O4: 1810 | P4: 09/19/88 | Q4: F | R4: Married | S4: US Citizen | T4: No | U4: White | V4: 40670 | W4: 9/24/2012 | X4: hours | Y4: Voluntarily Terminated | Z4: Production | AA4: Kissy Sullivan | AB4: 20 | AC4: LinkedIn | AD4: Fully Meets | AE4: 3.02 | AF4: 3 | AG4: 0 | AH4: 5/15/2012 | AI4: 0 | AJ4: 3
A5: Alagbe Trina | B5: 10088 | C5: 1 | D5: 1 | E5: 0 | F5: 1 | G5: 5 | H5: 3 | I5: 0 | J5: 64991 | K5: 0 | L5: 19 | M5: Production Technician I | N5: MA | O5: 1886 | P5: 09/27/88 | Q5: F | R5: Married | S5: US Citizen | T5: No | U5: White | V5: 39630 | X5: N/A-StillEmployed | Y5: Active | Z5: Production | AA5: Elijiah Gray | AB5: 16 | AC5: Indeed | AD5: Fully Meets | AE5: 4.84 | AF5: 5 | AG5: 0 | AH5: 43525 | AI5: 0 | AJ5: 15
A6: Anderson Carol | B6: 10069 | C6: 0 | D6: 2 | E6: 0 | F6: 5 | G6: 5 | H6: 3 | I6: 0 | J6: 50825 | K6: 1 | L6: 19 | M6: Production Technician I | N6: MA | O6: 2169 | P6: 32729 | Q6: F | R6: Divorced | S6: US Citizen | T6: No | U6: White | V6: 40854 | W6: 42530 | X6: return to school | Y6: Voluntarily Terminated | Z6: Production | AA6: Webster Butler | AB6: 39 | AC6: Google Search | AD6: Fully Meets | AE6: 5.00 | AF6: 4 | AG6: 0 | AH6: 42371 | AI6: 0 | AJ6: 2
A7: Anderson Linda | B7: 10002 | C7: 0 | D7: 0 | E7: 0 | F7: 1 | G7: 5 | H7: 4 | I7: 0 | J7: 57568 | K7: 0 | L7: 19 | M7: Production Technician I | N7: MA | O7: 1844 | P7: 05/22/77 | Q7: F | R7: Single | S7: US Citizen | T7: No | U7: White | V7: 41153 | X7: N/A-StillEmployed | Y7: Active | Z7: Production | AA7: Amy Dunn | AB7: 11 | AC7: LinkedIn | AD7: Exceeds | AE7: 5.00 | AF7: 5 | AG7: 0 | AH7: 43647 | AI7: 0 | AJ7: 15
A8: Andreola Colby | B8: 10194 | C8: 0 | D8: 0 | E8: 0 | F8: 1 | G8: 4 | H8: 3 | I8: 0 | J8: 95660 | K8: 0 | L8: 24 | M8: Software Engineer | N8: MA | O8: 2110 | P8: 05/24/79 | Q8: F | R8: Single | S8: US Citizen | T8: No | U8: White | V8: 41923 | X8: N/A-StillEmployed | Y8: Active | Z8: Software Engineering | AA8: Alex Sweetwater | AB8: 10 | AC8: LinkedIn | AD8: Fully Meets | AE8: 3.04 | AF8: 3 | AG8: 4 | AH8: 43497 | AI8: 0 | AJ8: 19
A9: Athwal Sam | B9: 10062 | C9: 0 | D9: 4 | E9: 1 | F9: 1 | G9: 5 | H9: 3 | I9: 0 | J9: 59365 | K9: 0 | L9: 19 | M9: Production Technician I | N9: MA | O9: 2199 | P9: 02/18/83 | Q9: M | R9: Widowed | S9: US Citizen | T9: No | U9: White | V9: 9/30/2013 | X9: N/A-StillEmployed | Y9: Active | Z9: Production | AA9: Ketsia Liebig | AB9: 19 | AC9: Employee Referral | AD9: Fully Meets | AE9: 5.00 | AF9: 4 | AG9: 0 | AH9: 2/25/2019 | AI9: 0 | AJ9: 19
A10: Bachiochi Linda | B10: 10114 | C10: 0 | D10: 0 | E10: 0 | F10: 3 | G10: 5 | H10: 3 | I10: 1 | J10: 47837 | K10: 0 | L10: 19 | M10: Production Technician I | N10: MA | O10: 1902 | P10: 25874 | Q10: F | R10: Single | S10: US Citizen | T10: No | U10: Black or African American | V10: 39971 | X10: N/A-StillEmployed | Y10: Active | Z10: Production | AA10: Brannon Miller | AB10: 12 | AC10: Diversity Job Fair | AD10: Fully Meets | AE10: 4.46 | AF10: 3 | AG10: 0 | AH10: 1/25/2019 | AI10: 0 | AJ10: 4
A11: Bacong Alejandro | B11: 10250 | C11: 0 | D11: 2 | E11: 1 | F11: 1 | G11: 3 | H11: 3 | I11: 0 | J11: 50178 | K11: 0 | L11: 14 | M11: IT Support | N11: MA | O11: 1886 | P11: 32325 | Q11: M | R11: Divorced | S11: US Citizen | T11: No | U11: White | V11: 42125 | X11: N/A-StillEmployed | Y11: Active | Z11: IT/IS | AA11: Peter Monroe | AB11: 7 | AC11: Indeed | AD11: Fully Meets | AE11: 5.00 | AF11: 5 | AG11: 6 | AH11: 2/18/2019 | AI11: 0 | AJ11: 16
A12: Baczenski Rachael | B12: 10252 | C12: 1 | D12: 1 | E12: 0 | F12: 5 | G12: 5 | H12: 3 | I12: 1 | J12: 54670 | K12: 1 | L12: 19 | M12: Production Technician I | N12: MA | O12: 1902 | P12: 27364 | Q12: F | R12: Married | S12: US Citizen | T12: Yes | U12: Black or African American | V12: 40817 | W12: 43070 | X12: Another position | Y12: Voluntarily Terminated | Z12: Production | AA12: David Stanley | AB12: 14 | AC12: Diversity Job Fair | AD12: Fully Meets | AE12: 4.20 | AF12: 4 | AG12: 0 | AH12: 1/30/2016 | AI12: 0 | AJ12: 12
A13: Barbara Thomas | B13: 10242 | C13: 1 | D13: 1 | E13: 1 | F13: 5 | G13: 5 | H13: 3 | I13: 1 | J13: 47211 | K13: 1 | L13: 19 | M13: Production Technician I | N13: MA | O13: 2062 | P13: 02/21/74 | Q13: M | R13: Married | S13: US Citizen | T13: Yes | U13: Black or African American | V13: 40943 | W13: 9/19/2016 | X13: unhappy | Y13: Voluntarily Terminated | Z13: Production | AA13: Kissy Sullivan | AB13: 20 | AC13: Diversity Job Fair | AD13: Fully Meets | AE13: 4.20 | AF13: 3 | AG13: 0 | AH13: 42526 | AI13: 0 | AJ13: 15
A14: Barbossa Hector | B14: 10012 | C14: 0 | D14: 2 | E14: 1 | F14: 1 | G14: 3 | H14: 4 | I14: 1 | J14: 92328 | K14: 0 | L14: 9 | M14: Data Analyst | N14: TX | O14: 78230 | P14: 32240 | Q14: M | R14: Divorced | S14: US Citizen | T14: No | U14: Black or African American | V14: 41923 | X14: N/A-StillEmployed | Y14: Active | Z14: IT/IS | AA14: Simon Roup | AB14: 4 | AC14: Diversity Job Fair | AD14: Exceeds | AE14: 4.28 | AF14: 4 | AG14: 5 | AH14: 2/25/2019 | AI14: 0 | AJ14: 9
A15: Barone Francesco A | B15: 10265 | C15: 0 | D15: 0 | E15: 1 | F15: 1 | G15: 5 | H15: 3 | I15: 0 | J15: 58709 | K15: 0 | L15: 19 | M15: Production Technician I | N15: MA | O15: 1810 | P15: 07/20/83 | Q15: M | R15: Single | S15: US Citizen | T15: No | U15: Two or more races | V15: 2/20/2012 | X15: N/A-StillEmployed | Y15: Active | Z15: Production | AA15: Kelley Spirea | AB15: 18 | AC15: Google Search | AD15: Fully Meets | AE15: 4.60 | AF15: 4 | AG15: 0 | AH15: 2/14/2019 | AI15: 0 | AJ15: 7
A16: Barton Nader | B16: 10066 | C16: 0 | D16: 2 | E16: 1 | F16: 5 | G16: 5 | H16: 3 | I16: 0 | J16: 52505 | K16: 1 | L16: 19 | M16: Production Technician I | N16: MA | O16: 2747 | P16: 07/15/77 | Q16: M | R16: Divorced | S16: US Citizen | T16: No | U16: White | V16: 9/24/2012 | W16: 42890 | X16: Another position | Y16: Voluntarily Terminated | Z16: Production | AA16: Michael Albert | AB16: 22 | AC16: On-line Web application | AD16: Fully Meets | AE16: 5.00 | AF16: 5 | AG16: 0 | AH16: 42769 | AI16: 0 | AJ16: 1
A17: Bates Norman | B17: 10061 | C17: 0 | D17: 0 | E17: 1 | F17: 4 | G17: 5 | H17: 3 | I17: 0 | J17: 57834 | K17: 1 | L17: 19 | M17: Production Technician I | N17: MA | O17: 2050 | P17: 10/18/81 | Q17: M | R17: Single | S17: US Citizen | T17: No | U17: White | V17: 2/21/2011 | W17: 42833 | X17: attendance | Y17: Terminated for Cause | Z17: Production | AA17: Kelley Spirea | AB17: 18 | AC17: Google Search | AD17: Fully Meets | AE17: 5.00 | AF17: 4 | AG17: 0 | AH17: 42859 | AI17: 0 | AJ17: 20
A18: Beak Kimberly | B18: 10023 | C18: 1 | D18: 1 | E18: 0 | F18: 2 | G18: 5 | H18: 4 | I18: 0 | J18: 70131 | K18: 0 | L18: 20 | M18: Production Technician II | N18: MA | O18: 2145 | P18: 04/17/66 | Q18: F | R18: Married | S18: US Citizen | T18: No | U18: White | V18: 7/21/2016 | X18: N/A-StillEmployed | Y18: Active | Z18: Production | AA18: Kelley Spirea | AB18: 18 | AC18: Employee Referral | AD18: Exceeds | AE18: 4.40 | AF18: 3 | AG18: 0 | AH18: 1/14/2019 | AI18: 0 | AJ18: 16
A19: Beatrice Courtney | B19: 10055 | C19: 0 | D19: 0 | E19: 0 | F19: 1 | G19: 5 | H19: 3 | I19: 0 | J19: 59026 | K19: 0 | L19: 19 | M19: Production Technician I | N19: MA | O19: 1915 | P19: 10/27/70 | Q19: F | R19: Single | S19: Eligible NonCitizen | T19: No | U19: White | V19: 40637 | X19: N/A-StillEmployed | Y19: Active | Z19: Production | AA19: Elijiah Gray | AB19: 16 | AC19: Google Search | AD19: Fully Meets | AE19: 5.00 | AF19: 5 | AG19: 0 | AH19: 1/14/2019 | AI19: 0 | AJ19: 12
A20: Becker Renee | B20: 10245 | C20: 0 | D20: 0 | E20: 0 | F20: 4 | G20: 3 | H20: 3 | I20: 0 | J20: 110000 | K20: 1 | L20: 8 | M20: Database Administrator | N20: MA | O20: 2026 | P20: 31506 | Q20: F | R20: Single | S20: US Citizen | T20: Yes | U20: White | V20: 41827 | W20: 42347 | X20: performance | Y20: Terminated for Cause | Z20: IT/IS | AA20: Simon Roup | AB20: 4 | AC20: Google Search | AD20: Fully Meets | AE20: 4.50 | AF20: 4 | AG20: 5 | AH20: 1/15/2015 | AI20: 0 | AJ20: 8
A21: Becker Scott | B21: 10277 | C21: 0 | D21: 0 | E21: 1 | F21: 3 | G21: 5 | H21: 3 | I21: 0 | J21: 53250 | K21: 0 | L21: 19 | M21: Production Technician I | N21: MA | O21: 2452 | P21: 29010 | Q21: M | R21: Single | S21: US Citizen | T21: No | U21: Asian | V21: 41493 | X21: N/A-StillEmployed | Y21: Active | Z21: Production | AA21: Webster Butler | AC21: LinkedIn | AD21: Fully Meets | AE21: 4.20 | AF21: 4 | AG21: 0 | AH21: 43770 | AI21: 0 | AJ21: 13
A22: Bernstein Sean | B22: 10046 | C22: 0 | D22: 0 | E22: 1 | F22: 1 | G22: 5 | H22: 3 | I22: 0 | J22: 51044 | K22: 0 | L22: 19 | M22: Production Technician I | N22: MA | O22: 2072 | P22: 12/22/70 | Q22: M | R22: Single | S22: US Citizen | T22: Yes | U22: White | V22: 40943 | X22: N/A-StillEmployed | Y22: Active | Z22: Production | AA22: Amy Dunn | AB22: 11 | AC22: Google Search | AD22: Fully Meets | AE22: 5.00 | AF22: 3 | AG22: 0 | AH22: 1/14/2019 | AI22: 0 | AJ22: 13
A23: Biden Lowan M | B23: 10226 | C23: 0 | D23: 2 | E23: 0 | F23: 1 | G23: 5 | H23: 3 | I23: 0 | J23: 64919 | K23: 0 | L23: 19 | M23: Production Technician I | N23: MA | O23: 2027 | P23: 12/27/58 | Q23: F | R23: Divorced | S23: US Citizen | T23: No | U23: Asian | V23: 8/19/2013 | X23: N/A-StillEmployed | Y23: Active | Z23: Production | AA23: Ketsia Liebig | AB23: 19 | AC23: Indeed | AD23: Fully Meets | AE23: 4.20 | AF23: 3 | AG23: 0 | AH23: 43739 | AI23: 0 | AJ23: 2
A24: Billis Helen | B24: 10003 | C24: 1 | D24: 1 | E24: 0 | F24: 1 | G24: 5 | H24: 4 | I24: 0 | J24: 62910 | K24: 0 | L24: 19 | M24: Production Technician I | N24: MA | O24: 2031 | P24: 32517 | Q24: F | R24: Married | S24: US Citizen | T24: No | U24: White | V24: 41827 | X24: N/A-StillEmployed | Y24: Active | Z24: Production | AA24: Brannon Miller | AB24: 12 | AC24: Indeed | AD24: Exceeds | AE24: 5.00 | AF24: 3 | AG24: 0 | AH24: 2/27/2019 | AI24: 0 | AJ24: 19
A25: Blount Dianna | B25: 10294 | C25: 0 | D25: 0 | E25: 0 | F25: 1 | G25: 5 | H25: 2 | I25: 0 | J25: 66441 | K25: 0 | L25: 20 | M25: Production Technician II | N25: MA | O25: 2171 | P25: 09/21/90 | Q25: F | R25: Single | S25: US Citizen | T25: No | U25: White | V25: 40637 | X25: N/A-StillEmployed | Y25: Active | Z25: Production | AA25: Michael Albert | AB25: 22 | AC25: CareerBuilder | AD25: Needs Improvement | AE25: 2.00 | AF25: 3 | AG25: 0 | AH25: 2/27/2019 | AI25: 2 | AJ25: 3
A26: Bondwell Betsy | B26: 10267 | C26: 0 | D26: 0 | E26: 0 | F26: 5 | G26: 5 | H26: 3 | I26: 0 | J26: 57815 | K26: 1 | L26: 20 | M26: Production Technician II | N26: MA | O26: 2210 | P26: 01/16/67 | Q26: F | R26: Single | S26: US Citizen | T26: No | U26: White | V26: 40817 | W26: 41733 | X26: career change | Y26: Voluntarily Terminated | Z26: Production | AA26: Elijiah Gray | AB26: 16 | AC26: Google Search | AD26: Fully Meets | AE26: 4.80 | AF26: 5 | AG26: 0 | AH26: 41732 | AI26: 0 | AJ26: 5
A27: Booth Frank | B27: 10199 | C27: 0 | D27: 0 | E27: 1 | F27: 4 | G27: 3 | H27: 3 | I27: 0 | J27: 103613 | K27: 1 | L27: 30 | M27: Enterprise Architect | N27: CT | O27: 6033 | P27: 07/30/64 | Q27: M | R27: Single | S27: US Citizen | T27: No | U27: Black or African American | V27: 2/17/2014 | W27: 2/19/2016 | X27: Learned that he is a gangster | Y27: Terminated for Cause | Z27: IT/IS | AA27: Simon Roup | AB27: 4 | AC27: LinkedIn | AD27: Fully Meets | AE27: 3.50 | AF27: 5 | AG27: 7 | AH27: 42644 | AI27: 0 | AJ27: 2
A28: Boutwell Bonalyn | B28: 10081 | C28: 1 | D28: 1 | E28: 0 | F28: 1 | G28: 1 | H28: 3 | I28: 1 | J28: 106367 | K28: 0 | L28: 26 | M28: Sr. Accountant | N28: MA | O28: 2468 | P28: 31871 | Q28: F | R28: Married | S28: US Citizen | T28: No | U28: Black or African American | V28: 2/16/2015 | X28: N/A-StillEmployed | Y28: Active | Z28: Admin Offices | AA28: Brandon R. LeBlanc | AB28: 3 | AC28: Diversity Job Fair | AD28: Fully Meets | AE28: 5.00 | AF28: 4 | AG28: 3 | AH28: 2/18/2019 | AI28: 0 | AJ28: 4
A29: Bozzi Charles | B29: 10175 | C29: 0 | D29: 0 | E29: 1 | F29: 5 | G29: 5 | H29: 3 | I29: 0 | J29: 74312 | K29: 1 | L29: 18 | M29: Production Manager | N29: MA | O29: 1901 | P29: 25844 | Q29: M | R29: Single | S29: US Citizen | T29: No | U29: Asian | V29: 9/30/2013 | W29: 41828 | X29: retiring | Y29: Voluntarily Terminated | Z29: Production | AA29: Janet King | AB29: 2 | AC29: Indeed | AD29: Fully Meets | AE29: 3.39 | AF29: 3 | AG29: 0 | AH29: 2/20/2014 | AI29: 0 | AJ29: 14
A30: Brill Donna | B30: 10177 | C30: 1 | D30: 1 | E30: 0 | F30: 5 | G30: 5 | H30: 3 | I30: 0 | J30: 53492 | K30: 1 | L30: 19 | M30: Production Technician I | N30: MA | O30: 1701 | P30: 08/24/90 | Q30: F | R30: Married | S30: US Citizen | T30: No | U30: White | V30: 40943 | W30: 6/15/2013 | X30: Another position | Y30: Voluntarily Terminated | Z30: Production | AA30: David Stanley | AB30: 14 | AC30: Google Search | AD30: Fully Meets | AE30: 3.35 | AF30: 4 | AG30: 0 | AH30: 41367 | AI30: 0 | AJ30: 6
A31: Brown Mia | B31: 10238 | C31: 1 | D31: 1 | E31: 0 | F31: 1 | G31: 1 | H31: 3 | I31: 1 | J31: 63000 | K31: 0 | L31: 1 | M31: Accountant I | N31: MA | O31: 1450 | P31: 11/24/87 | Q31: F | R31: Married | S31: US Citizen | T31: No | U31: Black or African American | V31: 10/27/2008 | X31: N/A-StillEmployed | Y31: Active | Z31: Admin Offices | AA31: Brandon R. LeBlanc | AB31: 1 | AC31: Diversity Job Fair | AD31: Fully Meets | AE31: 4.50 | AF31: 2 | AG31: 6 | AH31: 1/15/2019 | AI31: 0 | AJ31: 14
A32: Buccheri Joseph | B32: 10184 | C32: 0 | D32: 0 | E32: 1 | F32: 1 | G32: 5 | H32: 3 | I32: 0 | J32: 65288 | K32: 0 | L32: 20 | M32: Production Technician II | N32: MA | O32: 1013 | P32: 07/28/83 | Q32: M | R32: Single | S32: US Citizen | T32: No | U32: White | V32: 9/29/2014 | X32: N/A-StillEmployed | Y32: Active | Z32: Production | AA32: Webster Butler | AC32: Google Search | AD32: Fully Meets | AE32: 3.19 | AF32: 3 | AG32: 0 | AH32: 43467 | AI32: 0 | AJ32: 9
A33: Bugali Josephine | B33: 10203 | C33: 0 | D33: 3 | E33: 0 | F33: 3 | G33: 5 | H33: 3 | I33: 1 | J33: 64375 | K33: 0 | L33: 19 | M33: Production Technician I | N33: MA | O33: 2043 | P33: 10/30/69 | Q33: F | R33: Separated | S33: US Citizen | T33: No | U33: Black or African American | V33: 41589 | X33: N/A-StillEmployed | Y33: Active | Z33: Production | AA33: Kissy Sullivan | AB33: 20 | AC33: Diversity Job Fair | AD33: Fully Meets | AE33: 3.50 | AF33: 5 | AG33: 0 | AH33: 1/21/2019 | AI33: 0 | AJ33: 17
A34: Bunbury Jessica | B34: 10188 | C34: 1 | D34: 1 | E34: 0 | F34: 5 | G34: 6 | H34: 3 | I34: 0 | J34: 74326 | K34: 1 | L34: 3 | M34: Area Sales Manager | N34: VA | O34: 21851 | P34: 23382 | Q34: F | R34: Married | S34: Eligible NonCitizen | T34: No | U34: Black or African American | V34: 8/15/2011 | W34: 41678 | X34: Another position | Y34: Voluntarily Terminated | Z34: Sales | AA34: John Smith | AB34: 17 | AC34: Google Search | AD34: Fully Meets | AE34: 3.14 | AF34: 5 | AG34: 0 | AH34: 41549 | AI34: 1 | AJ34: 19
A35: Burke Joelle | B35: 10107 | C35: 0 | D35: 0 | E35: 0 | F35: 1 | G35: 5 | H35: 3 | I35: 0 | J35: 63763 | K35: 0 | L35: 20 | M35: Production Technician II | N35: MA | O35: 2148 | P35: 29254 | Q35: F | R35: Single | S35: US Citizen | T35: No | U35: Black or African American | V35: 41032 | X35: N/A-StillEmployed | Y35: Active | Z35: Production | AA35: Amy Dunn | AB35: 11 | AC35: Employee Referral | AD35: Fully Meets | AE35: 4.51 | AF35: 4 | AG35: 0 | AH35: 2/21/2019 | AI35: 0 | AJ35: 3
A36: Burkett Benjamin | B36: 10181 | C36: 1 | D36: 1 | E36: 1 | F36: 1 | G36: 5 | H36: 3 | I36: 0 | J36: 62162 | K36: 0 | L36: 20 | M36: Production Technician II | N36: MA | O36: 1890 | P36: 08/19/77 | Q36: M | R36: Married | S36: US Citizen | T36: No | U36: White | V36: 40637 | X36: N/A-StillEmployed | Y36: Active | Z36: Production | AA36: Ketsia Liebig | AB36: 19 | AC36: Indeed | AD36: Fully Meets | AE36: 3.25 | AF36: 5 | AG36: 0 | AH36: 1/14/2019 | AI36: 0 | AJ36: 15
A37: Cady Max | B37: 10150 | C37: 0 | D37: 0 | E37: 1 | F37: 1 | G37: 4 | H37: 3 | I37: 0 | J37: 77692 | K37: 0 | L37: 25 | M37: Software Engineering Manager | N37: MA | O37: 2184 | P37: 11/22/66 | Q37: M | R37: Single | S37: US Citizen | T37: No | U37: White | V37: 8/15/2011 | X37: N/A-StillEmployed | Y37: Active | Z37: Software Engineering | AA37: Jennifer Zamora | AB37: 5 | AC37: Google Search | AD37: Fully Meets | AE37: 3.84 | AF37: 3 | AG37: 5 | AH37: 1/21/2019 | AI37: 0 | AJ37: 4
A38: Candie Calvin | B38: 10001 | C38: 0 | D38: 0 | E38: 1 | F38: 1 | G38: 5 | H38: 4 | I38: 0 | J38: 72640 | K38: 0 | L38: 18 | M38: Production Manager | N38: MA | O38: 2169 | P38: 30567 | Q38: M | R38: Single | S38: US Citizen | T38: No | U38: White | V38: 1/28/2016 | X38: N/A-StillEmployed | Y38: Active | Z38: Production | AA38: Janet King | AB38: 2 | AC38: Indeed | AD38: Exceeds | AE38: 5.00 | AF38: 3 | AG38: 0 | AH38: 2/22/2019 | AI38: 0 | AJ38: 14
A39: Carabbio Judith | B39: 10085 | C39: 0 | D39: 0 | E39: 0 | F39: 1 | G39: 4 | H39: 3 | I39: 0 | J39: 93396 | K39: 0 | L39: 24 | M39: Software Engineer | N39: MA | O39: 2132 | P39: 31901 | Q39: F | R39: Single | S39: US Citizen | T39: No | U39: White | V39: 41589 | X39: N/A-StillEmployed | Y39: Active | Z39: Software Engineering | AA39: Alex Sweetwater | AB39: 10 | AC39: Indeed | AD39: Fully Meets | AE39: 4.96 | AF39: 4 | AG39: 6 | AH39: 1/30/2019 | AI39: 0 | AJ39: 3
A40: Carey Michael | B40: 10115 | C40: 0 | D40: 0 | E40: 1 | F40: 1 | G40: 5 | H40: 3 | I40: 0 | J40: 52846 | K40: 0 | L40: 19 | M40: Production Technician I | N40: MA | O40: 1701 | P40: 30349 | Q40: M | R40: Single | S40: US Citizen | T40: No | U40: Black or African American | V40: 3/31/2014 | X40: N/A-StillEmployed | Y40: Active | Z40: Production | AA40: Kelley Spirea | AB40: 18 | AC40: LinkedIn | AD40: Fully Meets | AE40: 4.43 | AF40: 3 | AG40: 0 | AH40: 43467 | AI40: 0 | AJ40: 14
...

Sheet Feuil3
A3: Étiquettes de lignes | B3: Somme de Termd2 | C3: Somme de Termd
A4: Admin Offices | B4: 0.019230769 | C4: 2
A5: Executive Office | B5: 0 | C5: 0
A6: IT/IS | B6: 0.096153846 | C6: 10
A7: Production | B7: 0.79807692 | C7: 83
A8: Sales | B8: 0.048076923 | C8: 5
A9: Software Engineering | B9: 0.038461538 | C9: 4
A10: (vide) | B10: 0
A11: Total général | B11: 1 | C11: 104

Sheet Feuil4
A3: Étiquettes de lignes | B3: Moyenne de Salary
A4: Exceeds | B4: 77144.865
A5: Fully Meets | B5: 68421.025
A6: Needs Improvement | B6: 68407.556
A7: PIP | B7: 57956
A8: (vide)
A9: Total général | B9: 69020.685

Sheet Feuil5
A3: Étiquettes de lignes | B3: Nombre de Recrutment
A4: CareerBuilder | B4: 23
A5: Diversity Job Fair | B5: 29
A6: Employee Referral | B6: 31
A7: Google Search | B7: 49
A8: Indeed | B8: 87
A9: LinkedIn | B9: 76
A10: On-line Web application | B10: 1
A11: Other | B11: 2
A12: Website | B12: 13
A13: (vide)
A14: Total général | B14: 311

Sheet Feuil6
A3: Étiquettes de lignes | B3: Moyenne de Absences
A4: Exceeds | B4: 10.486486
A5: Fully Meets | B5: 10.242798
A6: Needs Improvement | B6: 11.333333
A7: PIP | B7: 7.9230769
A8: (vide)
A9: Total général | B9: 10.237942

Sheet Feuil9
A3: Nombre de Employee_Name | B3: Étiquettes de colonnes
A4: Étiquettes de lignes | B4: FAIBLE | C4: SURVEILLER | D4: (vide) | E4: Total général
A5: Admin Offices | B5: 0.019292605 | C5: 0.0096463023 | D5: 0 | E5: 0.028938907
A6: Executive Office | B6: 0.0032154341 | C6: 0 | D6: 0 | E6: 0.0032154341
A7: IT/IS | B7: 0.080385852 | C7: 0.080385852 | D7: 0 | E7: 0.1607717
A8: Production | B8: 0.33440514 | C8: 0.33762058 | D8: 0 | E8: 0.67202572
A9: Sales | B9: 0.048231511 | C9: 0.051446945 | D9: 0 | E9: 0.099678457
A10: Software Engineering | B10: 0.022508039 | C10: 0.012861736 | D10: 0 | E10: 0.035369775
A11: (vide) | B11: 0 | C11: 0 | D11: 0 | E11: 0
A12: Total général | B12: 0.50803859 | C12: 0.49196141 | D12: 0 | E12: 1

Sheet Feuil1
A1: Employee_Name | B1: EmpID | C1: MarriedID | D1: MaritalStatuID | E1: GenderIS | F1: EmpstatutID | G1: DeptID | H1: PerfScoreID | I1: FromDiver | J1: Salary | K1: Termd | L1: PositionID | M1: Psition | N1: State | O1: Zip | P1: DOB | Q1: Sex | R1: MaritalDESC | S1: Citizedesc | T1: HispanicLatin | U1: Racedesc | V1: Dateofhire | W1: Dateoftermi | X1: Termreason | Y1: Employement | Z1: Department | AA1: Managernat | AB1: ManagerID | AC1: Recrutment | AD1: Performance | AE1: Engagement | AF1: EmploySatisfy | AG1: SpecialProjet | AH1: LastPERF | AI1: DayLatel | AJ1: Absences | AK1: Age | AL1: Anciennete | AM1: Type_depart | AN1: Trancge_Age | AO1: Groupe_PERFORMANCE | AP1: Risque_départ
A2: Adinolfi Wilson K | B2: 10026 | C2: 0 | D2: 0 | E2: 1 | F2: 1 | G2: 5 | H2: 4 | I2: 0 | J2: 62506 | K2: 0 | L2: 19 | M2: Production Technician I | N2: MA | O2: 1960 | P2: 30596 | Q2: M | R2: Single | S2: US Citizen | T2: No | U2: White | V2: 40670 | X2: N/A-StillEmployed | Y2: Active | Z2: Production | AA2: Michael Albert | AB2: 22 | AC2: LinkedIn | AD2: Exceeds | AE2: 4.60 | AF2: 5 | AG2: 0 | AH2: 1/17/2019 | AI2: 0 | AJ2: 1 | AK2: =DATEDIF(P2, TODAY(), "Y") -> 42 | AL2: =INT((IF(K2=0, TODAY(), W2) - V2) / 365.25) -> 14 | AM2: =IF(K2=0, "Actif", IF(OR(X2="Another position", X2="more money", X2="unhappy", X2="career change", X2="return to school", X2="relocation out of area", X2="medical issues", X2="military", X2="retiring"), "Volontaire", "Involontaire")) -> Actif | AN2: =IF(AK2<30, "Moins de 30", IF(AK2<45, "30-44 ans", IF(AK2<60, "45-59 ans", "60 ans et plus"))) -> 30-44 ans | AO2: =IF(H2=1, "PIP", IF(H2=2, "Needs Improvement", IF(H2=3, "Fully Meets", IF(H2=4, "Exceeds", "Non défini")))) -> Exceeds | AP2: =IF(AND(AE2<3, AF2<3, AJ2>15), "CRITIQUE", IF(OR(AE2<3, AJ2>10), "SURVEILLER", "FAIBLE")) -> FAIBLE
A3: Ait Sidi Karthikeyan | B3: 10084 | C3: 1 | D3: 1 | E3: 1 | F3: 5 | G3: 3 | H3: 3 | I3: 0 | J3: 104437 | K3: 1 | L3: 27 | M3: Sr. DBA | N3: MA | O3: 2148 | P3: 27519 | Q3: M | R3: Married | S3: US Citizen | T3: No | U3: White | V3: 42093 | W3: 42537 | X3: career change | Y3: Voluntarily Terminated | Z3: IT/IS | AA3: Simon Roup | AB3: 4 | AC3: Indeed | AD3: Fully Meets | AE3: 4.96 | AF3: 3 | AG3: 6 | AH3: 2/24/2016 | AI3: 0 | AJ3: 17 | AK3: =DATEDIF(P2, TODAY(), "Y") -> 42 | AL3: =INT((IF(K3=0, TODAY(), W3) - V3) / 365.25) -> 1 | AM3: =IF(K3=0, "Actif", IF(OR(X3="Another position", X3="more money", X3="unhappy", X3="career change", X3="return to school", X3="relocation out of area", X3="medical issues", X3="military", X3="retiring"), "Volontaire", "Involontaire")) -> Volontaire | AN3: =IF(AK3<30, "Moins de 30", IF(AK3<45, "30-44 ans", IF(AK3<60, "45-59 ans", "60 ans et plus"))) -> 30-44 ans | AO3: =IF(H3=1, "PIP", IF(H3=2, "Needs Improvement", IF(H3=3, "Fully Meets", IF(H3=4, "Exceeds", "Non défini")))) -> Fully Meets | AP3: =IF(AND(AE3<3, AF3<3, AJ3>15), "CRITIQUE", IF(OR(AE3<3, AJ3>10), "SURVEILLER", "FAIBLE")) -> SURVEILLER
A4: Akinkuolie Sarah | B4: 10196 | C4: 1 | D4: 1 | E4: 0 | F4: 5 | G4: 5 | H4: 3 | I4: 0 | J4: 64955 | K4: 1 | L4: 20 | M4: Production Technician II | N4: MA | O4: 1810 | P4: 32405 | Q4: F | R4: Married | S4: US Citizen | T4: No | U4: White | V4: 40670 | W4: 41176 | X4: hours | Y4: Voluntarily Terminated | Z4: Production | AA4: Kissy Sullivan | AB4: 20 | AC4: LinkedIn | AD4: Fully Meets | AE4: 3.02 | AF4: 3 | AG4: 0 | AH4: 5/15/2012 | AI4: 0 | AJ4: 3 | AK4: =DATEDIF(P4, TODAY(), "Y") -> 37 | AL4: =INT((IF(K4=0, TODAY(), W4) - V4) / 365.25) -> 1 | AM4: =IF(K4=0, "Actif", IF(OR(X4="Another position", X4="more money", X4="unhappy", X4="career change", X4="return to school", X4="relocation out of area", X4="medical issues", X4="military", X4="retiring"), "Volontaire", "Involontaire")) -> Involontaire | AN4: =IF(AK4<30, "Moins de 30", IF(AK4<45, "30-44 ans", IF(AK4<60, "45-59 ans", "60 ans et plus"))) -> 30-44 ans | AO4: =IF(H4=1, "PIP", IF(H4=2, "Needs Improvement", IF(H4=3, "Fully Meets", IF(H4=4, "Exceeds", "Non défini")))) -> Fully Meets | AP4: =IF(AND(AE4<3, AF4<3, AJ4>15), "CRITIQUE", IF(OR(AE4<3, AJ4>10), "SURVEILLER", "FAIBLE")) -> FAIBLE
A5: Alagbe Trina | B5: 10088 | C5: 1 | D5: 1 | E5: 0 | F5: 1 | G5: 5 | H5: 3 | I5: 0 | J5: 64991 | K5: 0 | L5: 19 | M5: Production Technician I | N5: MA | O5: 1886 | P5: 32413 | Q5: F | R5: Married | S5: US Citizen | T5: No | U5: White | V5: 39630 | X5: N/A-StillEmployed | Y5: Active | Z5: Production | AA5: Elijiah Gray | AB5: 16 | AC5: Indeed | AD5: Fully Meets | AE5: 4.84 | AF5: 5 | AG5: 0 | AH5: 43525 | AI5: 0 | AJ5: 15 | AK5: =DATEDIF(P5, TODAY(), "Y") -> 37 | AL5: =INT((IF(K5=0, TODAY(), W5) - V5) / 365.25) -> 17 | AM5: =IF(K5=0, "Actif", IF(OR(X5="Another position", X5="more money", X5="unhappy", X5="career change", X5="return to school", X5="relocation out of area", X5="medical issues", X5="military", X5="retiring"), "Volontaire", "Involontaire")) -> Actif | AN5: =IF(AK5<30, "Moins de 30", IF(AK5<45, "30-44 ans", IF(AK5<60, "45-59 ans", "60 ans et plus"))) -> 30-44 ans | AO5: =IF(H5=1, "PIP", IF(H5=2, "Needs Improvement", IF(H5=3, "Fully Meets", IF(H5=4, "Exceeds", "Non défini")))) -> Fully Meets | AP5: =IF(AND(AE5<3, AF5<3, AJ5>15), "CRITIQUE", IF(OR(AE5<3, AJ5>10), "SURVEILLER", "FAIBLE")) -> SURVEILLER
A6: Anderson Carol | B6: 10069 | C6: 0 | D6: 2 | E6: 0 | F6: 5 | G6: 5 | H6: 3 | I6: 0 | J6: 50825 | K6: 1 | L6: 19 | M6: Production Technician I | N6: MA | O6: 2169 | P6: 32729 | Q6: F | R6: Divorced | S6: US Citizen | T6: No | U6: White | V6: 40854 | W6: 42530 | X6: return to school | Y6: Voluntarily Terminated | Z6: Production | AA6: Webster Butler | AB6: 39 | AC6: Google Search | AD6: Fully Meets | AE6: 5.00 | AF6: 4 | AG6: 0 | AH6: 42371 | AI6: 0 | AJ6: 2 | AK6: =DATEDIF(P6, TODAY(), "Y") -> 36 | AL6: =INT((IF(K6=0, TODAY(), W6) - V6) / 365.25) -> 4 | AM6: =IF(K6=0, "Actif", IF(OR(X6="Another position", X6="more money", X6="unhappy", X6="career change", X6="return to school", X6="relocation out of area", X6="medical issues", X6="military", X6="retiring"), "Volontaire", "Involontaire")) -> Volontaire | AN6: =IF(AK6<30, "Moins de 30", IF(AK6<45, "30-44 ans", IF(AK6<60, "45-59 ans", "60 ans et plus"))) -> 30-44 ans | AO6: =IF(H6=1, "PIP", IF(H6=2, "Needs Improvement", IF(H6=3, "Fully Meets", IF(H6=4, "Exceeds", "Non défini")))) -> Fully Meets | AP6: =IF(AND(AE6<3, AF6<3, AJ6>15), "CRITIQUE", IF(OR(AE6<3, AJ6>10), "SURVEILLER", "FAIBLE")) -> FAIBLE
A7: Anderson Linda | B7: 10002 | C7: 0 | D7: 0 | E7: 0 | F7: 1 | G7: 5 | H7: 4 | I7: 0 | J7: 57568 | K7: 0 | L7: 19 | M7: Production Technician I | N7: MA | O7: 1844 | P7: 28267 | Q7: F | R7: Single | S7: US Citizen | T7: No | U7: White | V7: 41153 | X7: N/A-StillEmployed | Y7: Active | Z7: Production | AA7: Amy Dunn | AB7: 11 | AC7: LinkedIn | AD7: Exceeds | AE7: 5.00 | AF7: 5 | AG7: 0 | AH7: 43647 | AI7: 0 | AJ7: 15 | AK7: =DATEDIF(P7, TODAY(), "Y") -> 48 | AL7: =INT((IF(K7=0, TODAY(), W7) - V7) / 365.25) -> 13 | AM7: =IF(K7=0, "Actif", IF(OR(X7="Another position", X7="more money", X7="unhappy", X7="career change", X7="return to school", X7="relocation out of area", X7="medical issues", X7="military", X7="retiring"), "Volontaire", "Involontaire")) -> Actif | AN7: =IF(AK7<30, "Moins de 30", IF(AK7<45, "30-44 ans", IF(AK7<60, "45-59 ans", "60 ans et plus"))) -> 45-59 ans | AO7: =IF(H7=1, "PIP", IF(H7=2, "Needs Improvement", IF(H7=3, "Fully Meets", IF(H7=4, "Exceeds", "Non défini")))) -> Exceeds | AP7: =IF(AND(AE7<3, AF7<3, AJ7>15), "CRITIQUE", IF(OR(AE7<3, AJ7>10), "SURVEILLER", "FAIBLE")) -> SURVEILLER
A8: Andreola Colby | B8: 10194 | C8: 0 | D8: 0 | E8: 0 | F8: 1 | G8: 4 | H8: 3 | I8: 0 | J8: 95660 | K8: 0 | L8: 24 | M8: Software Engineer | N8: MA | O8: 2110 | P8: 28999 | Q8: F | R8: Single | S8: US Citizen | T8: No | U8: White | V8: 41923 | X8: N/A-StillEmployed | Y8: Active | Z8: Software Engineering | AA8: Alex Sweetwater | AB8: 10 | AC8: LinkedIn | AD8: Fully Meets | AE8: 3.04 | AF8: 3 | AG8: 4 | AH8: 43497 | AI8: 0 | AJ8: 19 | AK8: =DATEDIF(P8, TODAY(), "Y") -> 46 | AL8: =INT((IF(K8=0, TODAY(), W8) - V8) / 365.25) -> 11 | AM8: =IF(K8=0, "Actif", IF(OR(X8="Another position", X8="more money", X8="unhappy", X8="career change", X8="return to school", X8="relocation out of area", X8="medical issues", X8="military", X8="retiring"), "Volontaire", "Involontaire")) -> Actif | AN8: =IF(AK8<30, "Moins de 30", IF(AK8<45, "30-44 ans", IF(AK8<60, "45-59 ans", "60 ans et plus"))) -> 45-59 ans | AO8: =IF(H8=1, "PIP", IF(H8=2, "Needs Improvement", IF(H8=3, "Fully Meets", IF(H8=4, "Exceeds", "Non défini")))) -> Fully Meets | AP8: =IF(AND(AE8<3, AF8<3, AJ8>15), "CRITIQUE", IF(OR(AE8<3, AJ8>10), "SURVEILLER", "FAIBLE")) -> SURVEILLER
A9: Athwal Sam | B9: 10062 | C9: 0 | D9: 4 | E9: 1 | F9: 1 | G9: 5 | H9: 3 | I9: 0 | J9: 59365 | K9: 0 | L9: 19 | M9: Production Technician I | N9: MA | O9: 2199 | P9: 30365 | Q9: M | R9: Widowed | S9: US Citizen | T9: No | U9: White | V9: 41547 | X9: N/A-StillEmployed | Y9: Active | Z9: Production | AA9: Ketsia Liebig | AB9: 19 | AC9: Employee Referral | AD9: Fully Meets | AE9: 5.00 | AF9: 4 | AG9: 0 | AH9: 2/25/2019 | AI9: 0 | AJ9: 19 | AK9: =DATEDIF(P9, TODAY(), "Y") -> 43 | AL9: =INT((IF(K9=0, TODAY(), W9) - V9) / 365.25) -> 12 | AM9: =IF(K9=0, "Actif", IF(OR(X9="Another position", X9="more money", X9="unhappy", X9="career change", X9="return to school", X9="relocation out of area", X9="medical issues", X9="military", X9="retiring"), "Volontaire", "Involontaire")) -> Actif | AN9: =IF(AK9<30, "Moins de 30", IF(AK9<45, "30-44 ans", IF(AK9<60, "45-59 ans", "60 ans et plus"))) -> 30-44 ans | AO9: =IF(H9=1, "PIP", IF(H9=2, "Needs Improvement", IF(H9=3, "Fully Meets", IF(H9=4, "Exceeds", "Non défini")))) -> Fully Meets | AP9: =IF(AND(AE9<3, AF9<3, AJ9>15), "CRITIQUE", IF(OR(AE9<3, AJ9>10), "SURVEILLER", "FAIBLE")) -> SURVEILLER
A10: Bachiochi Linda | B10: 10114 | C10: 0 | D10: 0 | E10: 0 | F10: 3 | G10: 5 | H10: 3 | I10: 1 | J10: 47837 | K10: 0 | L10: 19 | M10: Production Technician I | N10: MA | O10: 1902 | P10: 25874 | Q10: F | R10: Single | S10: US Citizen | T10: No | U10: Black or African American | V10: 39971 | X10: N/A-StillEmployed | Y10: Active | Z10: Production | AA10: Brannon Miller | AB10: 12 | AC10: Diversity Job Fair | AD10: Fully Meets | AE10: 4.46 | AF10: 3 | AG10: 0 | AH10: 1/25/2019 | AI10: 0 | AJ10: 4 | AK10: =DATEDIF(P10, TODAY(), "Y") -> 55 | AL10: =INT((IF(K10=0, TODAY(), W10) - V10) / 365.25) -> 16 | AM10: =IF(K10=0, "Actif", IF(OR(X10="Another position", X10="more money", X10="unhappy", X10="career change", X10="return to school", X10="relocation out of area", X10="medical issues", X10="military", X10="retiring"), "Volontaire", "Involontaire")) -> Actif | AN10: =IF(AK10<30, "Moins de 30", IF(AK10<45, "30-44 ans", IF(AK10<60, "45-59 ans", "60 ans et plus"))) -> 45-59 ans | AO10: =IF(H10=1, "PIP", IF(H10=2, "Needs Improvement", IF(H10=3, "Fully Meets", IF(H10=4, "Exceeds", "Non défini")))) -> Fully Meets | AP10: =IF(AND(AE10<3, AF10<3, AJ10>15), "CRITIQUE", IF(OR(AE10<3, AJ10>10), "SURVEILLER", "FAIBLE")) -> FAIBLE
A11: Bacong Alejandro | B11: 10250 | C11: 0 | D11: 2 | E11: 1 | F11: 1 | G11: 3 | H11: 3 | I11: 0 | J11: 50178 | K11: 0 | L11: 14 | M11: IT Support | N11: MA | O11: 1886 | P11: 32325 | Q11: M | R11: Divorced | S11: US Citizen | T11: No | U11: White | V11: 42125 | X11: N/A-StillEmployed | Y11: Active | Z11: IT/IS | AA11: Peter Monroe | AB11: 7 | AC11: Indeed | AD11: Fully Meets | AE11: 5.00 | AF11: 5 | AG11: 6 | AH11: 2/18/2019 | AI11: 0 | AJ11: 16 | AK11: =DATEDIF(P11, TODAY(), "Y") -> 37 | AL11: =INT((IF(K11=0, TODAY(), W11) - V11) / 365.25) -> 10 | AM11: =IF(K11=0, "Actif", IF(OR(X11="Another position", X11="more money", X11="unhappy", X11="career change", X11="return to school", X11="relocation out of area", X11="medical issues", X11="military", X11="retiring"), "Volontaire", "Involontaire")) -> Actif | AN11: =IF(AK11<30, "Moins de 30", IF(AK11<45, "30-44 ans", IF(AK11<60, "45-59 ans", "60 ans et plus"))) -> 30-44 ans | AO11: =IF(H11=1, "PIP", IF(H11=2, "Needs Improvement", IF(H11=3, "Fully Meets", IF(H11=4, "Exceeds", "Non défini")))) -> Fully Meets | AP11: =IF(AND(AE11<3, AF11<3, AJ11>15), "CRITIQUE", IF(OR(AE11<3, AJ11>10), "SURVEILLER", "FAIBLE")) -> SURVEILLER
A12: Baczenski Rachael | B12: 10252 | C12: 1 | D12: 1 | E12: 0 | F12: 5 | G12: 5 | H12: 3 | I12: 1 | J12: 54670 | K12: 1 | L12: 19 | M12: Production Technician I | N12: MA | O12: 1902 | P12: 27364 | Q12: F | R12: Married | S12: US Citizen | T12: Yes | U12: Black or African American | V12: 40817 | W12: 43070 | X12: Another position | Y12: Voluntarily Terminated | Z12: Production | AA12: David Stanley | AB12: 14 | AC12: Diversity Job Fair | AD12: Fully Meets | AE12: 4.20 | AF12: 4 | AG12: 0 | AH12: 1/30/2016 | AI12: 0 | AJ12: 12 | AK12: =DATEDIF(P12, TODAY(), "Y") -> 51 | AL12: =INT((IF(K12=0, TODAY(), W12) - V12) / 365.25) -> 6 | AM12: =IF(K12=0, "Actif", IF(OR(X12="Another position", X12="more money", X12="unhappy", X12="career change", X12="return to school", X12="relocation out of area", X12="medical issues", X12="military", X12="retiring"), "Volontaire", "Involontaire")) -> Volontaire | AN12: =IF(AK12<30, "Moins de 30", IF(AK12<45, "30-44 ans", IF(AK12<60, "45-59 ans", "60 ans et plus"))) -> 45-59 ans | AO12: =IF(H12=1, "PIP", IF(H12=2, "Needs Improvement", IF(H12=3, "Fully Meets", IF(H12=4, "Exceeds", "Non défini")))) -> Fully Meets | AP12: =IF(AND(AE12<3, AF12<3, AJ12>15), "CRITIQUE", IF(OR(AE12<3, AJ12>10), "SURVEILLER", "FAIBLE")) -> SURVEILLER
A13: Barbara Thomas | B13: 10242 | C13: 1 | D13: 1 | E13: 1 | F13: 5 | G13: 5 | H13: 3 | I13: 1 | J13: 47211 | K13: 1 | L13: 19 | M13: Production Technician I | N13: MA | O13: 2062 | P13: 27081 | Q13: M | R13: Married | S13: US Citizen | T13: Yes | U13: Black or African American | V13: 40943 | W13: 42632 | X13: unhappy | Y13: Voluntarily Terminated | Z13: Production | AA13: Kissy Sullivan | AB13: 20 | AC13: Diversity Job Fair | AD13: Fully Meets | AE13: 4.20 | AF13: 3 | AG13: 0 | AH13: 42526 | AI13: 0 | AJ13: 15 | AK13: =DATEDIF(P13, TODAY(), "Y") -> 52 | AL13: =INT((IF(K13=0, TODAY(), W13) - V13) / 365.25) -> 4 | AM13: =IF(K13=0, "Actif", IF(OR(X13="Another position", X13="more money", X13="unhappy", X13="career change", X13="return to school", X13="relocation out of area", X13="medical issues", X13="military", X13="retiring"), "Volontaire", "Involontaire")) -> Volontaire | AN13: =IF(AK13<30, "Moins de 30", IF(AK13<45, "30-44 ans", IF(AK13<60, "45-59 ans", "60 ans et plus"))) -> 45-59 ans | AO13: =IF(H13=1, "PIP", IF(H13=2, "Needs Improvement", IF(H13=3, "Fully Meets", IF(H13=4, "Exceeds", "Non défini")))) -> Fully Meets | AP13: =IF(AND(AE13<3, AF13<3, AJ13>15), "CRITIQUE", IF(OR(AE13<3, AJ13>10), "SURVEILLER", "FAIBLE")) -> SURVEILLER
A14: Barbossa Hector | B14: 10012 | C14: 0 | D14: 2 | E14: 1 | F14: 1 | G14: 3 | H14: 4 | I14: 1 | J14: 92328 | K14: 0 | L14: 9 | M14: Data Analyst | N14: TX | O14: 78230 | P14: 32240 | Q14: M | R14: Divorced | S14: US Citizen | T14: No | U14: Black or African American | V14: 41923 | X14: N/A-StillEmployed | Y14: Active | Z14: IT/IS | AA14: Simon Roup | AB14: 4 | AC14: Diversity Job Fair | AD14: Exceeds | AE14: 4.28 | AF14: 4 | AG14: 5 | AH14: 2/25/2019 | AI14: 0 | AJ14: 9 | AK14: =DATEDIF(P14, TODAY(), "Y") -> 37 | AL14: =INT((IF(K14=0, TODAY(), W14) - V14) / 365.25) -> 11 | AM14: =IF(K14=0, "Actif", IF(OR(X14="Another position", X14="more money", X14="unhappy", X14="career change", X14="return to school", X14="relocation out of area", X14="medical issues", X14="military", X14="retiring"), "Volontaire", "Involontaire")) -> Actif | AN14: =IF(AK14<30, "Moins de 30", IF(AK14<45, "30-44 ans", IF(AK14<60, "45-59 ans", "60 ans et plus"))) -> 30-44 ans | AO14: =IF(H14=1, "PIP", IF(H14=2, "Needs Improvement", IF(H14=3, "Fully Meets", IF(H14=4, "Exceeds", "Non défini")))) -> Exceeds | AP14: =IF(AND(AE14<3, AF14<3, AJ14>15), "CRITIQUE", IF(OR(AE14<3, AJ14>10), "SURVEILLER", "FAIBLE")) -> FAIBLE
A15: Barone Francesco A | B15: 10265 | C15: 0 | D15: 0 | E15: 1 | F15: 1 | G15: 5 | H15: 3 | I15: 0 | J15: 58709 | K15: 0 | L15: 19 | M15: Production Technician I | N15: MA | O15: 1810 | P15: 30517 | Q15: M | R15: Single | S15: US Citizen | T15: No | U15: Two or more races | V15: 40959 | X15: N/A-StillEmployed | Y15: Active | Z15: Production | AA15: Kelley Spirea | AB15: 18 | AC15: Google Search | AD15: Fully Meets | AE15: 4.60 | AF15: 4 | AG15: 0 | AH15: 2/14/2019 | AI15: 0 | AJ15: 7 | AK15: =DATEDIF(P15, TODAY(), "Y") -> 42 | AL15: =INT((IF(K15=0, TODAY(), W15) - V15) / 365.25) -> 14 | AM15: =IF(K15=0, "Actif", IF(OR(X15="Another position", X15="more money", X15="unhappy", X15="career change", X15="return to school", X15="relocation out of area", X15="medical issues", X15="military", X15="retiring"), "Volontaire", "Involontaire")) -> Actif | AN15: =IF(AK15<30, "Moins de 30", IF(AK15<45, "30-44 ans", IF(AK15<60, "45-59 ans", "60 ans et plus"))) -> 30-44 ans | AO15: =IF(H15=1, "PIP", IF(H15=2, "Needs Improvement", IF(H15=3, "Fully Meets", IF(H15=4, "Exceeds", "Non défini")))) -> Fully Meets | AP15: =IF(AND(AE15<3, AF15<3, AJ15>15), "CRITIQUE", IF(OR(AE15<3, AJ15>10), "SURVEILLER", "FAIBLE")) -> FAIBLE
A16: Barton Nader | B16: 10066 | C16: 0 | D16: 2 | E16: 1 | F16: 5 | G16: 5 | H16: 3 | I16: 0 | J16: 52505 | K16: 1 | L16: 19 | M16: Production Technician I | N16: MA | O16: 2747 | P16: 28321 | Q16: M | R16: Divorced | S16: US Citizen | T16: No | U16: White | V16: 41176 | W16: 42890 | X16: Another position | Y16: Voluntarily Terminated | Z16: Production | AA16: Michael Albert | AB16: 22 | AC16: On-line Web application | AD16: Fully Meets | AE16: 5.00 | AF16: 5 | AG16: 0 | AH16: 42769 | AI16: 0 | AJ16: 1 | AK16: =DATEDIF(P16, TODAY(), "Y") -> 48 | AL16: =INT((IF(K16=0, TODAY(), W16) - V16) / 365.25) -> 4 | AM16: =IF(K16=0, "Actif", IF(OR(X16="Another position", X16="more money", X16="unhappy", X16="career change", X16="return to school", X16="relocation out of area", X16="medical issues", X16="military", X16="retiring"), "Volontaire", "Involontaire")) -> Volontaire | AN16: =IF(AK16<30, "Moins de 30", IF(AK16<45, "30-44 ans", IF(AK16<60, "45-59 ans", "60 ans et plus"))) -> 45-59 ans | AO16: =IF(H16=1, "PIP", IF(H16=2, "Needs Improvement", IF(H16=3, "Fully Meets", IF(H16=4, "Exceeds", "Non défini")))) -> Fully Meets | AP16: =IF(AND(AE16<3, AF16<3, AJ16>15), "CRITIQUE", IF(OR(AE16<3, AJ16>10), "SURVEILLER", "FAIBLE")) -> FAIBLE
A17: Bates Norman | B17: 10061 | C17: 0 | D17: 0 | E17: 1 | F17: 4 | G17: 5 | H17: 3 | I17: 0 | J17: 57834 | K17: 1 | L17: 19 | M17: Production Technician I | N17: MA | O17: 2050 | P17: 29877 | Q17: M | R17: Single | S17: US Citizen | T17: No | U17: White | V17: 40595 | W17: 42833 | X17: attendance | Y17: Terminated for Cause | Z17: Production | AA17: Kelley Spirea | AB17: 18 | AC17: Google Search | AD17: Fully Meets | AE17: 5.00 | AF17: 4 | AG17: 0 | AH17: 42859 | AI17: 0 | AJ17: 20 | AK17: =DATEDIF(P17, TODAY(), "Y") -> 44 | AL17: =INT((IF(K17=0, TODAY(), W17) - V17) / 365.25) -> 6 | AM17: =IF(K17=0, "Actif", IF(OR(X17="Another position", X17="more money", X17="unhappy", X17="career change", X17="return to school", X17="relocation out of area", X17="medical issues", X17="military", X17="retiring"), "Volontaire", "Involontaire")) -> Involontaire | AN17: =IF(AK17<30, "Moins de 30", IF(AK17<45, "30-44 ans", IF(AK17<60, "45-59 ans", "60 ans et plus"))) -> 30-44 ans | AO17: =IF(H17=1, "PIP", IF(H17=2, "Needs Improvement", IF(H17=3, "Fully Meets", IF(H17=4, "Exceeds", "Non défini")))) -> Fully Meets | AP17: =IF(AND(AE17<3, AF17<3, AJ17>15), "CRITIQUE", IF(OR(AE17<3, AJ17>10), "SURVEILLER", "FAIBLE")) -> SURVEILLER
A18: Beak Kimberly | B18: 10023 | C18: 1 | D18: 1 | E18: 0 | F18: 2 | G18: 5 | H18: 4 | I18: 0 | J18: 70131 | K18: 0 | L18: 20 | M18: Production Technician II | N18: MA | O18: 2145 | P18: 24214 | Q18: F | R18: Married | S18: US Citizen | T18: No | U18: White | V18: 42572 | X18: N/A-StillEmployed | Y18: Active | Z18: Production | AA18: Kelley Spirea | AB18: 18 | AC18: Employee Referral | AD18: Exceeds | AE18: 4.40 | AF18: 3 | AG18: 0 | AH18: 1/14/2019 | AI18: 0 | AJ18: 16 | AK18: =DATEDIF(P18, TODAY(), "Y") -> 59 | AL18: =INT((IF(K18=0, TODAY(), W18) - V18) / 365.25) -> 9 | AM18: =IF(K18=0, "Actif", IF(OR(X18="Another position", X18="more money", X18="unhappy", X18="career change", X18="return to school", X18="relocation out of area", X18="medical issues", X18="military", X18="retiring"), "Volontaire", "Involontaire")) -> Actif | AN18: =IF(AK18<30, "Moins de 30", IF(AK18<45, "30-44 ans", IF(AK18<60, "45-59 ans", "60 ans et plus"))) -> 45-59 ans | AO18: =IF(H18=1, "PIP", IF(H18=2, "Needs Improvement", IF(H18=3, "Fully Meets", IF(H18=4, "Exceeds", "Non défini")))) -> Exceeds | AP18: =IF(AND(AE18<3, AF18<3, AJ18>15), "CRITIQUE", IF(OR(AE18<3, AJ18>10), "SURVEILLER", "FAIBLE")) -> SURVEILLER
A19: Beatrice Courtney | B19: 10055 | C19: 0 | D19: 0 | E19: 0 | F19: 1 | G19: 5 | H19: 3 | I19: 0 | J19: 59026 | K19: 0 | L19: 19 | M19: Production Technician I | N19: MA | O19: 1915 | P19: 25868 | Q19: F | R19: Single | S19: Eligible NonCitizen | T19: No | U19: White | V19: 40637 | X19: N/A-StillEmployed | Y19: Active | Z19: Production | AA19: Elijiah Gray | AB19: 16 | AC19: Google Search | AD19: Fully Meets | AE19: 5.00 | AF19: 5 | AG19: 0 | AH19: 1/14/2019 | AI19: 0 | AJ19: 12 | AK19: =DATEDIF(P19, TODAY(), "Y") -> 55 | AL19: =INT((IF(K19=0, TODAY(), W19) - V19) / 365.25) -> 15 | AM19: =IF(K19=0, "Actif", IF(OR(X19="Another position", X19="more money", X19="unhappy", X19="career change", X19="return to school", X19="relocation out of area", X19="medical issues", X19="military", X19="retiring"), "Volontaire", "Involontaire")) -> Actif | AN19: =IF(AK19<30, "Moins de 30", IF(AK19<45, "30-44 ans", IF(AK19<60, "45-59 ans", "60 ans et plus"))) -> 45-59 ans | AO19: =IF(H19=1, "PIP", IF(H19=2, "Needs Improvement", IF(H19=3, "Fully Meets", IF(H19=4, "Exceeds", "Non défini")))) -> Fully Meets | AP19: =IF(AND(AE19<3, AF19<3, AJ19>15), "CRITIQUE", IF(OR(AE19<3, AJ19>10), "SURVEILLER", "FAIBLE")) -> SURVEILLER
A20: Becker Renee | B20: 10245 | C20: 0 | D20: 0 | E20: 0 | F20: 4 | G20: 3 | H20: 3 | I20: 0 | J20: 110000 | K20: 1 | L20: 8 | M20: Database Administrator | N20: MA | O20: 2026 | P20: 31506 | Q20: F | R20: Single | S20: US Citizen | T20: Yes | U20: White | V20: 41827 | W20: 42347 | X20: performance | Y20: Terminated for Cause | Z20: IT/IS | AA20: Simon Roup | AB20: 4 | AC20: Google Search | AD20: Fully Meets | AE20: 4.50 | AF20: 4 | AG20: 5 | AH20: 1/15/2015 | AI20: 0 | AJ20: 8 | AK20: =DATEDIF(P20, TODAY(), "Y") -> 40 | AL20: =INT((IF(K20=0, TODAY(), W20) - V20) / 365.25) -> 1 | AM20: =IF(K20=0, "Actif", IF(OR(X20="Another position", X20="more money", X20="unhappy", X20="career change", X20="return to school", X20="relocation out of area", X20="medical issues", X20="military", X20="retiring"), "Volontaire", "Involontaire")) -> Involontaire | AN20: =IF(AK20<30, "Moins de 30", IF(AK20<45, "30-44 ans", IF(AK20<60, "45-59 ans", "60 ans et plus"))) -> 30-44 ans | AO20: =IF(H20=1, "PIP", IF(H20=2, "Needs Improvement", IF(H20=3, "Fully Meets", IF(H20=4, "Exceeds", "Non défini")))) -> Fully Meets | AP20: =IF(AND(AE20<3, AF20<3, AJ20>15), "CRITIQUE", IF(OR(AE20<3, AJ20>10), "SURVEILLER", "FAIBLE")) -> FAIBLE
A21: Becker Scott | B21: 10277 | C21: 0 | D21: 0 | E21: 1 | F21: 3 | G21: 5 | H21: 3 | I21: 0 | J21: 53250 | K21: 0 | L21: 19 | M21: Production Technician I | N21: MA | O21: 2452 | P21: 29010 | Q21: M | R21: Single | S21: US Citizen | T21: No | U21: Asian | V21: 41493 | X21: N/A-StillEmployed | Y21: Active | Z21: Production | AA21: Webster Butler | AC21: LinkedIn | AD21: Fully Meets | AE21: 4.20 | AF21: 4 | AG21: 0 | AH21: 43770 | AI21: 0 | AJ21: 13 | AK21: =DATEDIF(P21, TODAY(), "Y") -> 46 | AL21: =INT((IF(K21=0, TODAY(), W21) - V21) / 365.25) -> 12 | AM21: =IF(K21=0, "Actif", IF(OR(X21="Another position", X21="more money", X21="unhappy", X21="career change", X21="return to school", X21="relocation out of area", X21="medical issues", X21="military", X21="retiring"), "Volontaire", "Involontaire")) -> Actif | AN21: =IF(AK21<30, "Moins de 30", IF(AK21<45, "30-44 ans", IF(AK21<60, "45-59 ans", "60 ans et plus"))) -> 45-59 ans | AO21: =IF(H21=1, "PIP", IF(H21=2, "Needs Improvement", IF(H21=3, "Fully Meets", IF(H21=4, "Exceeds", "Non défini")))) -> Fully Meets | AP21: =IF(AND(AE21<3, AF21<3, AJ21>15), "CRITIQUE", IF(OR(AE21<3, AJ21>10), "SURVEILLER", "FAIBLE")) -> SURVEILLER
A22: Bernstein Sean | B22: 10046 | C22: 0 | D22: 0 | E22: 1 | F22: 1 | G22: 5 | H22: 3 | I22: 0 | J22: 51044 | K22: 0 | L22: 19 | M22: Production Technician I | N22: MA | O22: 2072 | P22: 25924 | Q22: M | R22: Single | S22: US Citizen | T22: Yes | U22: White | V22: 40943 | X22: N/A-StillEmployed | Y22: Active | Z22: Production | AA22: Amy Dunn | AB22: 11 | AC22: Google Search | AD22: Fully Meets | AE22: 5.00 | AF22: 3 | AG22: 0 | AH22: 1/14/2019 | AI22: 0 | AJ22: 13 | AK22: =DATEDIF(P22, TODAY(), "Y") -> 55 | AL22: =INT((IF(K22=0, TODAY(), W22) - V22) / 365.25) -> 14 | AM22: =IF(K22=0, "Actif", IF(OR(X22="Another position", X22="more money", X22="unhappy", X22="career change", X22="return to school", X22="relocation out of area", X22="medical issues", X22="military", X22="retiring"), "Volontaire", "Involontaire")) -> Actif | AN22: =IF(AK22<30, "Moins de 30", IF(AK22<45, "30-44 ans", IF(AK22<60, "45-59 ans", "60 ans et plus"))) -> 45-59 ans | AO22: =IF(H22=1, "PIP", IF(H22=2, "Needs Improvement", IF(H22=3, "Fully Meets", IF(H22=4, "Exceeds", "Non défini")))) -> Fully Meets | AP22: =IF(AND(AE22<3, AF22<3, AJ22>15), "CRITIQUE", IF(OR(AE22<3, AJ22>10), "SURVEILLER", "FAIBLE")) -> SURVEILLER
A23: Biden Lowan M | B23: 10226 | C23: 0 | D23: 2 | E23: 0 | F23: 1 | G23: 5 | H23: 3 | I23: 0 | J23: 64919 | K23: 0 | L23: 19 | M23: Production Technician I | N23: MA | O23: 2027 | P23: 21546 | Q23: F | R23: Divorced | S23: US Citizen | T23: No | U23: Asian | V23: 41505 | X23: N/A-StillEmployed | Y23: Active | Z23: Production | AA23: Ketsia Liebig | AB23: 19 | AC23: Indeed | AD23: Fully Meets | AE23: 4.20 | AF23: 3 | AG23: 0 | AH23: 43739 | AI23: 0 | AJ23: 2 | AK23: =DATEDIF(P23, TODAY(), "Y") -> 67 | AL23: =INT((IF(K23=0, TODAY(), W23) - V23) / 365.25) -> 12 | AM23: =IF(K23=0, "Actif", IF(OR(X23="Another position", X23="more money", X23="unhappy", X23="career change", X23="return to school", X23="relocation out of area", X23="medical issues", X23="military", X23="retiring"), "Volontaire", "Involontaire")) -> Actif | AN23: =IF(AK23<30, "Moins de 30", IF(AK23<45, "30-44 ans", IF(AK23<60, "45-59 ans", "60 ans et plus"))) -> 60 ans et plus | AO23: =IF(H23=1, "PIP", IF(H23=2, "Needs Improvement", IF(H23=3, "Fully Meets", IF(H23=4, "Exceeds", "Non défini")))) -> Fully Meets | AP23: =IF(AND(AE23<3, AF23<3, AJ23>15), "CRITIQUE", IF(OR(AE23<3, AJ23>10), "SURVEILLER", "FAIBLE")) -> FAIBLE
A24: Billis Helen | B24: 10003 | C24: 1 | D24: 1 | E24: 0 | F24: 1 | G24: 5 | H24: 4 | I24: 0 | J24: 62910 | K24: 0 | L24: 19 | M24: Production Technician I | N24: MA | O24: 2031 | P24: 32517 | Q24: F | R24: Married | S24: US Citizen | T24: No | U24: White | V24: 41827 | X24: N/A-StillEmployed | Y24: Active | Z24: Production | AA24: Brannon Miller | AB24: 12 | AC24: Indeed | AD24: Exceeds | AE24: 5.00 | AF24: 3 | AG24: 0 | AH24: 2/27/2019 | AI24: 0 | AJ24: 19 | AK24: =DATEDIF(P24, TODAY(), "Y") -> 37 | AL24: =INT((IF(K24=0, TODAY(), W24) - V24) / 365.25) -> 11 | AM24: =IF(K24=0, "Actif", IF(OR(X24="Another position", X24="more money", X24="unhappy", X24="career change", X24="return to school", X24="relocation out of area", X24="medical issues", X24="military", X24="retiring"), "Volontaire", "Involontaire")) -> Actif | AN24: =IF(AK24<30, "Moins de 30", IF(AK24<45, "30-44 ans", IF(AK24<60, "45-59 ans", "60 ans et plus"))) -> 30-44 ans | AO24: =IF(H24=1, "PIP", IF(H24=2, "Needs Improvement", IF(H24=3, "Fully Meets", IF(H24=4, "Exceeds", "Non défini")))) -> Exceeds | AP24: =IF(AND(AE24<3, AF24<3, AJ24>15), "CRITIQUE", IF(OR(AE24<3, AJ24>10), "SURVEILLER", "FAIBLE")) -> SURVEILLER
A25: Blount Dianna | B25: 10294 | C25: 0 | D25: 0 | E25: 0 | F25: 1 | G25: 5 | H25: 2 | I25: 0 | J25: 66441 | K25: 0 | L25: 20 | M25: Production Technician II | N25: MA | O25: 2171 | P25: 33137 | Q25: F | R25: Single | S25: US Citizen | T25: No | U25: White | V25: 40637 | X25: N/A-StillEmployed | Y25: Active | Z25: Production | AA25: Michael Albert | AB25: 22 | AC25: CareerBuilder | AD25: Needs Improvement | AE25: 2.00 | AF25: 3 | AG25: 0 | AH25: 2/27/2019 | AI25: 2 | AJ25: 3 | AK25: =DATEDIF(P25, TODAY(), "Y") -> 35 | AL25: =INT((IF(K25=0, TODAY(), W25) - V25) / 365.25) -> 15 | AM25: =IF(K25=0, "Actif", IF(OR(X25="Another position", X25="more money", X25="unhappy", X25="career change", X25="return to school", X25="relocation out of area", X25="medical issues", X25="military", X25="retiring"), "Volontaire", "Involontaire")) -> Actif | AN25: =IF(AK25<30, "Moins de 30", IF(AK25<45, "30-44 ans", IF(AK25<60, "45-59 ans", "60 ans et plus"))) -> 30-44 ans | AO25: =IF(H25=1, "PIP", IF(H25=2, "Needs Improvement", IF(H25=3, "Fully Meets", IF(H25=4, "Exceeds", "Non défini")))) -> Needs Improvement | AP25: =IF(AND(AE25<3, AF25<3, AJ25>15), "CRITIQUE", IF(OR(AE25<3, AJ25>10), "SURVEILLER", "FAIBLE")) -> FAIBLE
A26: Bondwell Betsy | B26: 10267 | C26: 0 | D26: 0 | E26: 0 | F26: 5 | G26: 5 | H26: 3 | I26: 0 | J26: 57815 | K26: 1 | L26: 20 | M26: Production Technician II | N26: MA | O26: 2210 | P26: 24488 | Q26: F | R26: Single | S26: US Citizen | T26: No | U26: White | V26: 40817 | W26: 41733 | X26: career change | Y26: Voluntarily Terminated | Z26: Production | AA26: Elijiah Gray | AB26: 16 | AC26: Google Search | AD26: Fully Meets | AE26: 4.80 | AF26: 5 | AG26: 0 | AH26: 41732 | AI26: 0 | AJ26: 5 | AK26: =DATEDIF(P26, TODAY(), "Y") -> 59 | AL26: =INT((IF(K26=0, TODAY(), W26) - V26) / 365.25) -> 2 | AM26: =IF(K26=0, "Actif", IF(OR(X26="Another position", X26="more money", X26="unhappy", X26="career change", X26="return to school", X26="relocation out of area", X26="medical issues", X26="military", X26="retiring"), "Volontaire", "Involontaire")) -> Volontaire | AN26: =IF(AK26<30, "Moins de 30", IF(AK26<45, "30-44 ans", IF(AK26<60, "45-59 ans", "60 ans et plus"))) -> 45-59 ans | AO26: =IF(H26=1, "PIP", IF(H26=2, "Needs Improvement", IF(H26=3, "Fully Meets", IF(H26=4, "Exceeds", "Non défini")))) -> Fully Meets | AP26: =IF(AND(AE26<3, AF26<3, AJ26>15), "CRITIQUE", IF(OR(AE26<3, AJ26>10), "SURVEILLER", "FAIBLE")) -> FAIBLE
A27: Booth Frank | B27: 10199 | C27: 0 | D27: 0 | E27: 1 | F27: 4 | G27: 3 | H27: 3 | I27: 0 | J27: 103613 | K27: 1 | L27: 30 | M27: Enterprise Architect | N27: CT | O27: 6033 | P27: 23588 | Q27: M | R27: Single | S27: US Citizen | T27: No | U27: Black or African American | V27: 41687 | W27: 42419 | X27: Learned that he is a gangster | Y27: Terminated for Cause | Z27: IT/IS | AA27: Simon Roup | AB27: 4 | AC27: LinkedIn | AD27: Fully Meets | AE27: 3.50 | AF27: 5 | AG27: 7 | AH27: 42644 | AI27: 0 | AJ27: 2 | AK27: =DATEDIF(P27, TODAY(), "Y") -> 61 | AL27: =INT((IF(K27=0, TODAY(), W27) - V27) / 365.25) -> 2 | AM27: =IF(K27=0, "Actif", IF(OR(X27="Another position", X27="more money", X27="unhappy", X27="career change", X27="return to school", X27="relocation out of area", X27="medical issues", X27="military", X27="retiring"), "Volontaire", "Involontaire")) -> Involontaire | AN27: =IF(AK27<30, "Moins de 30", IF(AK27<45, "30-44 ans", IF(AK27<60, "45-59 ans", "60 ans et plus"))) -> 60 ans et plus | AO27: =IF(H27=1, "PIP", IF(H27=2, "Needs Improvement", IF(H27=3, "Fully Meets", IF(H27=4, "Exceeds", "Non défini")))) -> Fully Meets | AP27: =IF(AND(AE27<3, AF27<3, AJ27>15), "CRITIQUE", IF(OR(AE27<3, AJ27>10), "SURVEILLER", "FAIBLE")) -> FAIBLE
A28: Boutwell Bonalyn | B28: 10081 | C28: 1 | D28: 1 | E28: 0 | F28: 1 | G28: 1 | H28: 3 | I28: 1 | J28: 106367 | K28: 0 | L28: 26 | M28: Sr. Accountant | N28: MA | O28: 2468 | P28: 31871 | Q28: F | R28: Married | S28: US Citizen | T28: No | U28: Black or African American | V28: 42051 | X28: N/A-StillEmployed | Y28: Active | Z28: Admin Offices | AA28: Brandon R. LeBlanc | AB28: 3 | AC28: Diversity Job Fair | AD28: Fully Meets | AE28: 5.00 | AF28: 4 | AG28: 3 | AH28: 2/18/2019 | AI28: 0 | AJ28: 4 | AK28: =DATEDIF(P28, TODAY(), "Y") -> 39 | AL28: =INT((IF(K28=0, TODAY(), W28) - V28) / 365.25) -> 11 | AM28: =IF(K28=0, "Actif", IF(OR(X28="Another position", X28="more money", X28="unhappy", X28="career change", X28="return to school", X28="relocation out of area", X28="medical issues", X28="military", X28="retiring"), "Volontaire", "Involontaire")) -> Actif | AN28: =IF(AK28<30, "Moins de 30", IF(AK28<45, "30-44 ans", IF(AK28<60, "45-59 ans", "60 ans et plus"))) -> 30-44 ans | AO28: =IF(H28=1, "PIP", IF(H28=2, "Needs Improvement", IF(H28=3, "Fully Meets", IF(H28=4, "Exceeds", "Non défini")))) -> Fully Meets | AP28: =IF(AND(AE28<3, AF28<3, AJ28>15), "CRITIQUE", IF(OR(AE28<3, AJ28>10), "SURVEILLER", "FAIBLE")) -> FAIBLE
A29: Bozzi Charles | B29: 10175 | C29: 0 | D29: 0 | E29: 1 | F29: 5 | G29: 5 | H29: 3 | I29: 0 | J29: 74312 | K29: 1 | L29: 18 | M29: Production Manager | N29: MA | O29: 1901 | P29: 25844 | Q29: M | R29: Single | S29: US Citizen | T29: No | U29: Asian | V29: 41547 | W29: 41828 | X29: retiring | Y29: Voluntarily Terminated | Z29: Production | AA29: Janet King | AB29: 2 | AC29: Indeed | AD29: Fully Meets | AE29: 3.39 | AF29: 3 | AG29: 0 | AH29: 2/20/2014 | AI29: 0 | AJ29: 14 | AK29: =DATEDIF(P29, TODAY(), "Y") -> 55 | AL29: =INT((IF(K29=0, TODAY(), W29) - V29) / 365.25) -> 0 | AM29: =IF(K29=0, "Actif", IF(OR(X29="Another position", X29="more money", X29="unhappy", X29="career change", X29="return to school", X29="relocation out of area", X29="medical issues", X29="military", X29="retiring"), "Volontaire", "Involontaire")) -> Volontaire | AN29: =IF(AK29<30, "Moins de 30", IF(AK29<45, "30-44 ans", IF(AK29<60, "45-59 ans", "60 ans et plus"))) -> 45-59 ans | AO29: =IF(H29=1, "PIP", IF(H29=2, "Needs Improvement", IF(H29=3, "Fully Meets", IF(H29=4, "Exceeds", "Non défini")))) -> Fully Meets | AP29: =IF(AND(AE29<3, AF29<3, AJ29>15), "CRITIQUE", IF(OR(AE29<3, AJ29>10), "SURVEILLER", "FAIBLE")) -> SURVEILLER
A30: Brill Donna | B30: 10177 | C30: 1 | D30: 1 | E30: 0 | F30: 5 | G30: 5 | H30: 3 | I30: 0 | J30: 53492 | K30: 1 | L30: 19 | M30: Production Technician I | N30: MA | O30: 1701 | P30: 33109 | Q30: F | R30: Married | S30: US Citizen | T30: No | U30: White | V30: 40943 | W30: 41440 | X30: Another position | Y30: Voluntarily Terminated | Z30: Production | AA30: David Stanley | AB30: 14 | AC30: Google Search | AD30: Fully Meets | AE30: 3.35 | AF30: 4 | AG30: 0 | AH30: 41367 | AI30: 0 | AJ30: 6 | AK30: =DATEDIF(P30, TODAY(), "Y") -> 35 | AL30: =INT((IF(K30=0, TODAY(), W30) - V30) / 365.25) -> 1 | AM30: =IF(K30=0, "Actif", IF(OR(X30="Another position", X30="more money", X30="unhappy", X30="career change", X30="return to school", X30="relocation out of area", X30="medical issues", X30="military", X30="retiring"), "Volontaire", "Involontaire")) -> Volontaire | AN30: =IF(AK30<30, "Moins de 30", IF(AK30<45, "30-44 ans", IF(AK30<60, "45-59 ans", "60 ans et plus"))) -> 30-44 ans | AO30: =IF(H30=1, "PIP", IF(H30=2, "Needs Improvement", IF(H30=3, "Fully Meets", IF(H30=4, "Exceeds", "Non défini")))) -> Fully Meets | AP30: =IF(AND(AE30<3, AF30<3, AJ30>15), "CRITIQUE", IF(OR(AE30<3, AJ30>10), "SURVEILLER", "FAIBLE")) -> FAIBLE
A31: Brown Mia | B31: 10238 | C31: 1 | D31: 1 | E31: 0 | F31: 1 | G31: 1 | H31: 3 | I31: 1 | J31: 63000 | K31: 0 | L31: 1 | M31: Accountant I | N31: MA | O31: 1450 | P31: 32105 | Q31: F | R31: Married | S31: US Citizen | T31: No | U31: Black or African American | V31: 39748 | X31: N/A-StillEmployed | Y31: Active | Z31: Admin Offices | AA31: Brandon R. LeBlanc | AB31: 1 | AC31: Diversity Job Fair | AD31: Fully Meets | AE31: 4.50 | AF31: 2 | AG31: 6 | AH31: 1/15/2019 | AI31: 0 | AJ31: 14 | AK31: =DATEDIF(P31, TODAY(), "Y") -> 38 | AL31: =INT((IF(K31=0, TODAY(), W31) - V31) / 365.25) -> 17 | AM31: =IF(K31=0, "Actif", IF(OR(X31="Another position", X31="more money", X31="unhappy", X31="career change", X31="return to school", X31="relocation out of area", X31="medical issues", X31="military", X31="retiring"), "Volontaire", "Involontaire")) -> Actif | AN31: =IF(AK31<30, "Moins de 30", IF(AK31<45, "30-44 ans", IF(AK31<60, "45-59 ans", "60 ans et plus"))) -> 30-44 ans | AO31: =IF(H31=1, "PIP", IF(H31=2, "Needs Improvement", IF(H31=3, "Fully Meets", IF(H31=4, "Exceeds", "Non défini")))) -> Fully Meets | AP31: =IF(AND(AE31<3, AF31<3, AJ31>15), "CRITIQUE", IF(OR(AE31<3, AJ31>10), "SURVEILLER", "FAIBLE")) -> SURVEILLER
A32: Buccheri Joseph | B32: 10184 | C32: 0 | D32: 0 | E32: 1 | F32: 1 | G32: 5 | H32: 3 | I32: 0 | J32: 65288 | K32: 0 | L32: 20 | M32: Production Technician II | N32: MA | O32: 1013 | P32: 30525 | Q32: M | R32: Single | S32: US Citizen | T32: No | U32: White | V32: 41911 | X32: N/A-StillEmployed | Y32: Active | Z32: Production | AA32: Webster Butler | AC32: Google Search | AD32: Fully Meets | AE32: 3.19 | AF32: 3 | AG32: 0 | AH32: 43467 | AI32: 0 | AJ32: 9 | AK32: =DATEDIF(P32, TODAY(), "Y") -> 42 | AL32: =INT((IF(K32=0, TODAY(), W32) - V32) / 365.25) -> 11 | AM32: =IF(K32=0, "Actif", IF(OR(X32="Another position", X32="more money", X32="unhappy", X32="career change", X32="return to school", X32="relocation out of area", X32="medical issues", X32="military", X32="retiring"), "Volontaire", "Involontaire")) -> Actif | AN32: =IF(AK32<30, "Moins de 30", IF(AK32<45, "30-44 ans", IF(AK32<60, "45-59 ans", "60 ans et plus"))) -> 30-44 ans | AO32: =IF(H32=1, "PIP", IF(H32=2, "Needs Improvement", IF(H32=3, "Fully Meets", IF(H32=4, "Exceeds", "Non défini")))) -> Fully Meets | AP32: =IF(AND(AE32<3, AF32<3, AJ32>15), "CRITIQUE", IF(OR(AE32<3, AJ32>10), "SURVEILLER", "FAIBLE")) -> FAIBLE
